Workbook
Name equipes: equipes!$C$6:$C$11
Name feriados: feriados!$A$3:$A$1845
Name funcionarios: funcionários!$D$6:$D$11
Name me_fin: 'est1'!$C$59:$C$66
Name me_log: 'est3'!$C$59:$C$66
Name me_mkt: 'est2'!$C$59:$C$66
Name me_rh: 'est4'!$C$59:$C$66
Name params_ano: parametros!$B$2:$B$21
Name params_direcao: parametros!$I$2:$I$3
Name params_meses: parametros!$F$2:$F$13
Name params_pespc: parametros!$M$2:$M$5
Name params_qtda_anos: parametros!$D$2:$D$6
Name params_situacao: parametros!$L$2:$L$4
Name params_status: parametros!$G$2:$G$5
Name params_und: parametros!$J$2:$J$4
Name perspectiva_clientes: me!$H$6:$I$13
Name perspectiva_financeira: me!$D$6:$E$13
Name perspectiva_pi: me!$D$17:$E$24
Name perspectiva_rh: me!$H$17:$I$24

Sheet feriados
A1: CATANDUVA - SP | H1: RIBEIRÃO PRETO - SP
A2: DATA | B2: DIA DA SEMANA | C2: NOME | D2: ANO | E2: ALCANCE | H2: DATA | I2: DIA DA SEMANA | J2: NOME | K2: ANO | L2: ALCANCE
A3: =DATE(D3,1,1) -> 43466 | B3: =A3 -> 43466 | C3: Confraternização Universal | D3: 2019 | E3: NACIONAL | H3: =DATE(K3,1,1) -> 43466 | I3: =H3 -> 43466 | J3: Confraternização Universal | K3: 2019 | L3: NACIONAL
A4: =A7-48 -> 43528 | B4: =A4 -> 43528 | C4: Carnaval | D4: 2019 | E4: NACIONAL | H4: =H7-48 -> 43528 | I4: =H4 -> 43528 | J4: Carnaval | K4: 2019 | L4: NACIONAL
A5: =A7-47 -> 43529 | B5: =A5 -> 43529 | C5: Carnaval | D5: 2019 | E5: NACIONAL | H5: =H7-47 -> 43529 | I5: =H5 -> 43529 | J5: Carnaval | K5: 2019 | L5: NACIONAL
A6: =A7-2 -> 43574 | B6: =A6 -> 43574 | C6: Paixão de Cristo | D6: 2019 | E6: NACIONAL | H6: =H7-2 -> 43574 | I6: =H6 -> 43574 | J6: Paixão de Cristo | K6: 2019 | L6: NACIONAL
A7: =FLOOR(DAY(MINUTE(D7/38)/2+56)&"/5"&"/"&D7,7)-34 -> 43576 | B7: =A7 -> 43576 | C7: Páscoa | D7: 2019 | E7: NACIONAL | H7: =FLOOR(DAY(MINUTE(K7/38)/2+56)&"/5"&"/"&K7,7)-34 -> 43576 | I7: =H7 -> 43576 | J7: Páscoa | K7: 2019 | L7: NACIONAL
A8: =DATE(D8,4,14) -> 43569 | B8: =A8 -> 43569 | C8: Aniversário Da Cidade | D8: 2019 | E8: MUNICIPAL | H8: =DATE(K8,4,21) -> 43576 | I8: =H8 -> 43576 | J8: Tiradentes | K8: 2019 | L8: NACIONAL
A9: =DATE(D9,4,21) -> 43576 | B9: =A9 -> 43576 | C9: Tiradentes | D9: 2019 | E9: NACIONAL | H9: =DATE(K9,5,1) -> 43586 | I9: =H9 -> 43586 | J9: Dia do Trabalho | K9: 2019 | L9: NACIONAL
A10: =DATE(D10,5,1) -> 43586 | B10: =A10 -> 43586 | C10: Dia do Trabalho | D10: 2019 | E10: NACIONAL | H10: =DATE(K10,5,1)+(14-WEEKDAY(DATE(K10,5,1),2)) -> 43597 | I10: =H10 -> 43597 | J10: Dia das Mães | K10: 2019 | L10: NACIONAL
A11: =DATE(D11,5,1)+(14-WEEKDAY(DATE(D11,5,1),2)) -> 43597 | B11: =A11 -> 43597 | C11: Dia das Mães | D11: 2019 | E11: NACIONAL | H11: =H7+60 -> 43636 | I11: =H11 -> 43636 | J11: Corpus Cristi | K11: 2019 | L11: NACIONAL
A12: =A7+60 -> 43636 | B12: =A12 -> 43636 | C12: Corpus Cristi | D12: 2019 | E12: NACIONAL | H12: =DATE(K12,6,19) -> 43635 | I12: =H12 -> 43635 | J12: Aniversário Da Cidade | K12: 2019 | L12: MUNICIPAL
A13: =DATE(D13,7,9) -> 43655 | B13: =A13 -> 43655 | C13: Revolução constitucionalista | D13: 2019 | E13: ESTADUAL | H13: =DATE(K13,7,9) -> 43655 | I13: =H13 -> 43655 | J13: Revolução constitucionalista | K13: 2019 | L13: ESTADUAL
A14: =DATE(D14,8,8) -> 43685 | B14: =A14 -> 43685 | C14: Dia de São Domingos | D14: 2019 | E14: MUNICIPAL | H14: =DATE(K14,8,1)+(14-WEEKDAY(DATE(K14,8,1),2)) -> 43688 | I14: =H14 -> 43688 | J14: Dia do Pais | K14: 2019 | L14: NACIONAL
A15: =DATE(D15,8,1)+(14-WEEKDAY(DATE(D15,8,1),2)) -> 43688 | B15: =A15 -> 43688 | C15: Dia do Pais | D15: 2019 | E15: NACIONAL | H15: =DATE(K15,9,7) -> 43715 | I15: =H15 -> 43715 | J15: Independênica do Brasil | K15: 2019 | L15: NACIONAL
A16: =DATE(D16,9,7) -> 43715 | B16: =A16 -> 43715 | C16: Independênica do Brasil | D16: 2019 | E16: NACIONAL | H16: =DATE(K16,10,12) -> 43750 | I16: =H16 -> 43750 | J16: Nossa Srª Aparecida | K16: 2019 | L16: NACIONAL
A17: =DATE(D17,10,12) -> 43750 | B17: =A17 -> 43750 | C17: Nossa Srª Aparecida | D17: 2019 | E17: NACIONAL | H17: =DATE(K17,11,2) -> 43771 | I17: =H17 -> 43771 | J17: Finados | K17: 2019 | L17: NACIONAL
A18: =DATE(D18,11,2) -> 43771 | B18: =A18 -> 43771 | C18: Finados | D18: 2019 | E18: NACIONAL | H18: =DATE(K18,11,15) -> 43784 | I18: =H18 -> 43784 | J18: Proclamação da rebublica | K18: 2019 | L18: NACIONAL
A19: =DATE(D19,11,15) -> 43784 | B19: =A19 -> 43784 | C19: Proclamação da rebublica | D19: 2019 | E19: NACIONAL | H19: =DATE(K19,11,20) -> 43789 | I19: =H19 -> 43789 | J19: Conciênica Negra | K19: 2019 | L19: NACIONAL
A20: =DATE(D20,11,20) -> 43789 | B20: =A20 -> 43789 | C20: Conciênica Negra | D20: 2019 | E20: NACIONAL | H20: =DATE(K20,12,25) -> 43824 | I20: =H20 -> 43824 | J20: Natal | K20: 2019 | L20: NACIONAL
A21: =DATE(D21,12,25) -> 43824 | B21: =A21 -> 43824 | C21: Natal | D21: 2019 | E21: NACIONAL | H21: =DATE(K21,1,1) -> 43831 | I21: =H21 -> 43831 | J21: Confraternização Universal | K21: =K3+1 -> 2020 | L21: NACIONAL
A22: =DATE(D22,1,1) -> 43831 | B22: =A22 -> 43831 | C22: Confraternização Universal | D22: =D3+1 -> 2020 | E22: NACIONAL | H22: =H25-48 -> 43885 | I22: =H22 -> 43885 | J22: Carnaval | K22: =K4+1 -> 2020 | L22: NACIONAL
A23: =A26-48 -> 43885 | B23: =A23 -> 43885 | C23: Carnaval | D23: =D4+1 -> 2020 | E23: NACIONAL | H23: =H25-47 -> 43886 | I23: =H23 -> 43886 | J23: Carnaval | K23: =K5+1 -> 2020 | L23: NACIONAL
A24: =A26-47 -> 43886 | B24: =A24 -> 43886 | C24: Carnaval | D24: =D5+1 -> 2020 | E24: NACIONAL | H24: =H25-2 -> 43931 | I24: =H24 -> 43931 | J24: Paixão de Cristo | K24: =K6+1 -> 2020 | L24: NACIONAL
A25: =A26-2 -> 43931 | B25: =A25 -> 43931 | C25: Paixão de Cristo | D25: =D6+1 -> 2020 | E25: NACIONAL | H25: =FLOOR(DAY(MINUTE(K25/38)/2+56)&"/5"&"/"&K25,7)-34 -> 43933 | I25: =H25 -> 43933 | J25: Páscoa | K25: =K7+1 -> 2020 | L25: NACIONAL
A26: =FLOOR(DAY(MINUTE(D26/38)/2+56)&"/5"&"/"&D26,7)-34 -> 43933 | B26: =A26 -> 43933 | C26: Páscoa | D26: =D7+1 -> 2020 | E26: NACIONAL | H26: =DATE(K26,4,21) -> 43942 | I26: =H26 -> 43942 | J26: Tiradentes | K26: =K8+1 -> 2020 | L26: NACIONAL
A27: =DATE(D27,4,14) -> 43935 | B27: =A27 -> 43935 | C27: Aniversário Da Cidade | D27: =D8+1 -> 2020 | E27: MUNICIPAL | H27: =DATE(K27,5,1) -> 43952 | I27: =H27 -> 43952 | J27: Dia do Trabalho | K27: =K9+1 -> 2020 | L27: NACIONAL
A28: =DATE(D28,4,21) -> 43942 | B28: =A28 -> 43942 | C28: Tiradentes | D28: =D9+1 -> 2020 | E28: NACIONAL | H28: =DATE(K28,5,1)+(14-WEEKDAY(DATE(K28,5,1),2)) -> 43961 | I28: =H28 -> 43961 | J28: Dia das Mães | K28: =K10+1 -> 2020 | L28: NACIONAL
A29: =DATE(D29,5,1) -> 43952 | B29: =A29 -> 43952 | C29: Dia do Trabalho | D29: =D10+1 -> 2020 | E29: NACIONAL | H29: =H25+60 -> 43993 | I29: =H29 -> 43993 | J29: Corpus Cristi | K29: =K11+1 -> 2020 | L29: NACIONAL
A30: =DATE(D30,5,1)+(14-WEEKDAY(DATE(D30,5,1),2)) -> 43961 | B30: =A30 -> 43961 | C30: Dia das Mães | D30: =D11+1 -> 2020 | E30: NACIONAL | H30: =DATE(K30,6,19) -> 44001 | I30: =H30 -> 44001 | J30: Aniversário Da Cidade | K30: =K12+1 -> 2020 | L30: MUNICIPAL
A31: =A26+60 -> 43993 | B31: =A31 -> 43993 | C31: Corpus Cristi | D31: =D12+1 -> 2020 | E31: NACIONAL | H31: =DATE(K31,7,9) -> 44021 | I31: =H31 -> 44021 | J31: Revolução constitucionalista | K31: =K13+1 -> 2020 | L31: ESTADUAL
A32: =DATE(D32,7,9) -> 44021 | B32: =A32 -> 44021 | C32: Revolução constitucionalista | D32: =D13+1 -> 2020 | E32: ESTADUAL | H32: =DATE(K32,8,1)+(14-WEEKDAY(DATE(K32,8,1),2)) -> 44052 | I32: =H32 -> 44052 | J32: Dia do Pais | K32: =K14+1 -> 2020 | L32: NACIONAL
A33: =DATE(D33,8,8) -> 44051 | B33: =A33 -> 44051 | C33: Dia de São Domingos | D33: =D14+1 -> 2020 | E33: MUNICIPAL | H33: =DATE(K33,9,7) -> 44081 | I33: =H33 -> 44081 | J33: Independênica do Brasil | K33: =K15+1 -> 2020 | L33: NACIONAL
A34: =DATE(D34,8,1)+(14-WEEKDAY(DATE(D34,8,1),2)) -> 44052 | B34: =A34 -> 44052 | C34: Dia do Pais | D34: =D15+1 -> 2020 | E34: NACIONAL | H34: =DATE(K34,10,12) -> 44116 | I34: =H34 -> 44116 | J34: Nossa Srª Aparecida | K34: =K16+1 -> 2020 | L34: NACIONAL
A35: =DATE(D35,9,7) -> 44081 | B35: =A35 -> 44081 | C35: Independênica do Brasil | D35: =D16+1 -> 2020 | E35: NACIONAL | H35: =DATE(K35,11,2) -> 44137 | I35: =H35 -> 44137 | J35: Finados | K35: =K17+1 -> 2020 | L35: NACIONAL
A36: =DATE(D36,10,12) -> 44116 | B36: =A36 -> 44116 | C36: Nossa Srª Aparecida | D36: =D17+1 -> 2020 | E36: NACIONAL | H36: =DATE(K36,11,15) -> 44150 | I36: =H36 -> 44150 | J36: Proclamação da rebublica | K36: =K18+1 -> 2020 | L36: NACIONAL
A37: =DATE(D37,11,2) -> 44137 | B37: =A37 -> 44137 | C37: Finados | D37: =D18+1 -> 2020 | E37: NACIONAL | H37: =DATE(K37,11,20) -> 44155 | I37: =H37 -> 44155 | J37: Conciênica Negra | K37: =K19+1 -> 2020 | L37: NACIONAL
A38: =DATE(D38,11,15) -> 44150 | B38: =A38 -> 44150 | C38: Proclamação da rebublica | D38: =D19+1 -> 2020 | E38: NACIONAL | H38: =DATE(K38,12,25) -> 44190 | I38: =H38 -> 44190 | J38: Natal | K38: =K20+1 -> 2020 | L38: NACIONAL
A39: =DATE(D39,11,20) -> 44155 | B39: =A39 -> 44155 | C39: Conciênica Negra | D39: =D20+1 -> 2020 | E39: NACIONAL | H39: =DATE(K39,1,1) -> 44197 | I39: =H39 -> 44197 | J39: Confraternização Universal | K39: =K21+1 -> 2021 | L39: NACIONAL
A40: =DATE(D40,12,25) -> 44190 | B40: =A40 -> 44190 | C40: Natal | D40: =D21+1 -> 2020 | E40: NACIONAL | H40: =H43-48 -> 44242 | I40: =H40 -> 44242 | J40: Carnaval | K40: =K22+1 -> 2021 | L40: NACIONAL
...

Sheet parametros
A1: HOJE | B1: ANO | D1: QTDA DE ANOS | F1: MESES | G1: STATUS | I1: DIREÇÃO | J1: UNIDADE | K1: TIPO | L1: SITUAÇÃO | M1: PERSPECTIVAS | N1: SCORE METAS GLOBAIS | Q1: SCORE ACOMPANHAMENTO METAS | T1: SCORE ACOMPANHAMENTO PLANO DE AÇÃO | X1: SCORE POR COLABORADOR | AA1: META | AB1: PESO | AC1: PLANO | AD1: PESO | AE1: SCORE | AG1: POSIÇÃO | AH1: Diagnóstico (nome curto) | AI1: Leitura objetiva (o que está acontecendo) | AJ1: Frase norteadora (para o empresário) | AK1: Decisão recomendada (próximo passo)
A2: =TODAY() -> 46252 | B2: 2026 | C2: 1 | D2: 1 | E2: 1 | F2: Janeiro | G2: Aguardando Etapa | H2: 0 | I2: Aumentar | J2: Número | K2: Parcial | L2: Atrasado | M2: Perspectiva Financeira | N2: 0.6 | O2: 1 | P2: "Risco de não bater a meta global. Falta clareza de propósito, cadência ou capacidade. Prioridade: reclarificar o objetivo, reorganizar o plano e ativar alianças de suporte." | Q2: 0.6 | R2: 1 | S2: "A meta está em risco. Próximo passo: reclarificar o objetivo, reorganizar o plano de ataque e ativar apoio (alinhamento de time) para retomar a cadência." | T2: 0.6 | U2: 1 | V2: “A execução perdeu tração ou foi interrompida, comprometendo a credibilidade do plano.” | W2: VERMELHO | X2: 0.6 | Y2: 1 | Z2: “Mostra comprometimento consistente e alinhamento com os objetivos definidos.” | AA2: VERDE | AB2: =VLOOKUP(AA2,$R$13:$S$15,2,0) -> #N/A | AC2: VERDE | AD2: =VLOOKUP(AC2,$R$13:$S$15,2,0) -> #N/A | AE2: =IF(AB2>AD2,AD2/AB2,AB2/AD2) -> #N/A | AF2: =_xlfn.CONCAT(AA2,AC2) -> VERDEVERDE | AG2: 1 | AH2: Alinhado e consistente | AI2: Execução e resultado na mesma direção | AJ2: “O plano está funcionando e o resultado confirma. Agora é disciplina para consolidar e escalar.” | AK2: Manter cadência, padronizar o que funciona, aumentar a ambição gradual
A3: "Comunicar o diretor responsável pelo projeto imediatamente." | B3: =B2+1 -> 2027 | C3: 2 | D3: 2 | E3: 2 | F3: Fevereiro | G3: Em Andamento | H3: 0.25 | I3: Diminuir | J3: % | K3: Total | L3: Concluído | M3: Perspectiva de Clientes (Marketing) | N3: 0.79 | O3: 2 | P3: "Tração parcial. Há progresso, mas com vazamentos (processo, foco, capacidade ou funil). Prioridade: ajustar o plano e decidir o próximo passo crítico." | Q3: 0.79 | R3: 2 | S3: "A meta tem progresso, mas não está estável. Próximo passo: decidir o ajuste crítico e executar com persistência (um foco, um dono, um prazo curto)." | T3: 0.79 | U3: 2 | V3: “Há execução, mas sem consistência plena. A falta de cadência ou priorização reduz a força do plano.” | W3: AMARELO | X3: 0.79 | Y3: 2 | Z3: “Apresenta envolvimento pontual, precisando evoluir em autonomia e senso de prioridade.” | AA3: AMARELO | AB3: =VLOOKUP(AA3,$R$13:$S$15,2,0) -> #N/A | AC3: VERDE | AD3: =VLOOKUP(AC3,$R$13:$S$15,2,0) -> #N/A | AE3: =IF(AB3>AD3,AD3/AB3,AB3/AD3) -> #N/A | AF3: =_xlfn.CONCAT(AA3,AC3) -> AMARELO VERDE | AG3: 2 | AH3: Resultado sustentado por inércia | AI3: Resultado bom, mas execução perdeu força | AJ3: “O resultado ainda está bom, mas a execução enfraqueceu. Se não retomar a disciplina, a meta cai.” | AK3: Reforçar rotina, reativar entregas críticas, reduzir dispersão
B4: =B3+1 -> 2028 | C4: 3 | D4: 5 | E4: 3 | F4: Março | G4: Fase de Conclusão | H4: 0.7 | J4: R$ | L4: Em dia | M4: Perspectiva de Processos Internos (Logistica) | N4: 1 | O4: 3 | P4: "Execução consistente. O plano está funcionando. Prioridade: consolidar, padronizar e escalar com disciplina." | Q4: 1 | R4: 3 | S4: "A meta está sob controle e com execução consistente. Próximo passo: consolidar rotina, padronizar o que funcionou e ampliar escala sem perder qualidade." | T4: 1 | U4: 3 | V4: “A execução demonstra maturidade de gestão: ações priorizadas, acompanhamento regular e baixa fricção operacional.” | W4: VERDE | X4: 1 | Y4: 3 | Z4: “O engajamento atual não é compatível com a importância das entregas definidas.” | AA4: VERMELHO | AB4: =VLOOKUP(AA4,$R$13:$S$15,2,0) -> #N/A | AC4: VERDE | AD4: =VLOOKUP(AC4,$R$13:$S$15,2,0) -> #N/A | AE4: =IF(AB4>AD4,AD4/AB4,AB4/AD4) -> #N/A | AF4: =_xlfn.CONCAT(AA4,AC4) -> VERMELHOVERDE | AG4: 3 | AH4: Risco silencioso | AI4: Resultado bom, execução abandonada | AJ4: “Estamos colhendo do passado. Sem execução, esse verde não se sustenta.” | AK4: Retomar plano imediatamente, definir dono/prazo, reinstalar governança
B5: =B4+1 -> 2029 | C5: 4 | E5: 4 | F5: Abril | G5: Finalizado | H5: 1 | L5: Não Iniciado | M5: Perspectiva Aprendizagem (RH) | AA5: VERDE | AB5: =VLOOKUP(AA5,$R$13:$S$15,2,0) -> #N/A | AC5: AMARELO | AD5: =VLOOKUP(AC5,$R$13:$S$15,2,0) -> #N/A | AE5: =IF(AB5>AD5,AD5/AB5,AB5/AD5) -> #N/A | AF5: =_xlfn.CONCAT(AA5,AC5) -> VERDEAMARELO | AG5: 4 | AH5: Defasagem natural (ação → efeito) | AI5: Execução forte, efeito ainda não apareceu | AJ5: “O plano está forte e o resultado ainda está amadurecendo. Persistir e monitorar é melhor do que mudar por ansiedade.” | AK5: Persistir por um ciclo, monitorar indicador líder, checar premissas
B6: =B5+1 -> 2030 | C6: 5 | E6: 5 | F6: Maio | AA6: AMARELO | AB6: =VLOOKUP(AA6,$R$13:$S$15,2,0) -> #N/A | AC6: AMARELO | AD6: =VLOOKUP(AC6,$R$13:$S$15,2,0) -> #N/A | AE6: =IF(AB6>AD6,AD6/AB6,AB6/AD6) -> #N/A | AF6: =_xlfn.CONCAT(AA6,AC6) -> AMARELO AMARELO | AG6: 5 | AH6: Tração parcial | AI6: Tudo avança, mas lento | AJ6: “Há movimento, mas sem tração suficiente. Precisamos de foco em menos ações que gerem mais impacto.” | AK6: Priorizar 1–2 alavancas, cortar ruído, intensificar cadência
B7: =B6+1 -> 2031 | C7: 6 | E7: 6 | F7: Junho | AA7: VERMELHO | AB7: =VLOOKUP(AA7,$R$13:$S$15,2,0) -> #N/A | AC7: VERMELHO | AD7: =VLOOKUP(AC7,$R$13:$S$15,2,0) -> #N/A | AE7: =IF(AB7>AD7,AD7/AB7,AB7/AD7) -> #N/A | AF7: =_xlfn.CONCAT(AA7,AC7) -> VERMELHOVERMELHO | AG7: 6 | AH7: Reação insuficiente | AI7: Resultado morno e execução fraca | AJ7: “O resultado pede reação, mas o plano não está em campo. Precisamos reativar execução com decisão.” | AK7: Replanejar curto, definir 3 entregas, travar rotina semanal
B8: =B7+1 -> 2032 | C8: 7 | E8: 7 | F8: Julho | AA8: VERDE | AB8: =VLOOKUP(AA8,$R$13:$S$15,2,0) -> #N/A | AC8: VERMELHO | AD8: =VLOOKUP(AC8,$R$13:$S$15,2,0) -> #N/A | AE8: =IF(AB8>AD8,AD8/AB8,AB8/AD8) -> #N/A | AF8: =_xlfn.CONCAT(AA8,AC8) -> VERDEVERMELHO | AG8: 7 | AH8: Plano bem executado, alavanca errada | AI8: Execução ótima, resultado ruim | AJ8: “Estamos executando bem… mas talvez a alavanca não seja a correta para essa meta.” | AK8: Redesenhar estratégia/hipótese, trocar alavancas, validar causa-raiz
B9: =B8+1 -> 2033 | C9: 8 | E9: 8 | F9: Agosto | AA9: AMARELO | AB9: =VLOOKUP(AA9,$R$13:$S$15,2,0) -> #N/A | AC9: VERMELHO | AD9: =VLOOKUP(AC9,$R$13:$S$15,2,0) -> #N/A | AE9: =IF(AB9>AD9,AD9/AB9,AB9/AD9) -> #N/A | AF9: =_xlfn.CONCAT(AA9,AC9) -> AMARELO VERMELHO | AG9: 8 | AH9: Zona crítica | AI9: Resultado ruim, execução média | AJ9: “A resposta atual não é forte o bastante para virar o jogo. Precisamos de decisão e ajuste imediato.” | AK9: Aumentar intensidade, reforçar recursos, simplificar plano e atacar gargalo
B10: =B9+1 -> 2034 | C10: 9 | E10: 9 | F10: Setembro | AA10: VERMELHO | AB10: =VLOOKUP(AA10,$R$13:$S$15,2,0) -> #N/A | AC10: VERMELHO | AD10: =VLOOKUP(AC10,$R$13:$S$15,2,0) -> #N/A | AE10: =IF(AB10>AD10,AD10/AB10,AB10/AD10) -> #N/A | AF10: =_xlfn.CONCAT(AA10,AC10) -> VERMELHOVERMELHO | AG10: 9 | AH10: Alerta máximo | AI10: Não há resultado e não há execução
B11: =B10+1 -> 2035 | C11: 10 | E11: 10 | F11: Outubro
B12: =B11+1 -> 2036 | C12: 11 | E12: 11 | F12: Novembro
B13: =B12+1 -> 2037 | C13: 12 | E13: 12 | F13: Dezembro
B14: =B13+1 -> 2038 | C14: 13
B15: =B14+1 -> 2039 | C15: 14
B16: =B15+1 -> 2040 | C16: 15
B17: =B16+1 -> 2041 | C17: 16
B18: =B17+1 -> 2042 | C18: 17
B19: =B18+1 -> 2043 | C19: 18
B20: =B19+1 -> 2044 | C20: 19
B21: =B20+1 -> 2045 | C21: 20

Sheet id_org
C4: Sumário
C6: Dados da Empresa
C8: Nome:
C9: CNPJ:
C10: Endereço:
C11: Setor de atuação:
C12: Tempo de mercado:
C13: Nº de colaboradores:
C14: Faturamento médio:
C16: Ano de ínicio do planejamento | D16: 2026 | G16: Planejamento pára quantos anos? | H16: 1
C18: Diagnóstico Estratégico
C20: Missão
C21: Visão
C22: Valores
C23: Proposta de valor
C24: Principais produtos/serviços
C25: Diferenciais competitivos
C26: Principais Concorrentes
C28: Pontos Fortes | G28: Oportunidades
C35: Pontos Fracos | G35: Ameaças

Sheet equipes
C5: Áreas da Emepresa
C6: Produção
C7: Marketing
C8: Financeiro
C9: Tecnológica
C10: Atendimento
C11: Comercial

Sheet funcionários
C5: Áreas da Emepresa | D5: Cadastro de Funcionários
C6: Produção | D6: NATIELI
C7: Marketing | D7: COLL
C8: Financeiro
C9: Tecnológica
C10: Atendimento
C11: Comercial

Sheet me
C4: Direção | D4: Perspectiva Financeira | G4: Direção | H4: Perspectiva de Clientes (Marketing)
D5: Indicador | E5: Meta Global associada | H5: Indicador | I5: Meta Global associada
C6: Aumentar | D6: Faturamento | E6: Posicionamento premium | G6: Aumentar | H6: Base de clientes recorentes | I6: Posicionamento premium
C7: Aumentar | D7: Tiket Médio | E7: Posicionamento premium | G7: Aumentar | H7: Taxa de recompra (Fidelidade) | I7: Posicionamento premium
G8: Aumentar | H8: Agendamentos pelo instagram e whatsapp | I8: Posicionamento premium
G9: Aumentar | H9: Alavancar Engajamento médio | I9: Posicionamento premium
C15: Direção | D15: Perspectiva de Processos Internos (Logistica) | G15: Direção | H15: Perspectiva Aprendizagem (RH)
D16: Indicador | E16: Meta Global associada | H16: Indicador | I16: Meta Global associada
C17: Aumentar | D17: Crescimento | E17: Posicionamento premium

Sheet mg
C5: Metas globais da empresa | D5: Observações
C6: Posicionamento premium

Sheet est1
C4: Estratégia para | D4: Perspectiva Financeira
D5: 1 | Q5: =_xlfn.CONCAT(Q7,D5) -> Parcial1 | R5: =_xlfn.CONCAT(R7,D5) -> Total1 | T5: 2 | AF5: =_xlfn.CONCAT(AF7,T5) -> Parcial2 | AG5: =_xlfn.CONCAT(AG7,T5) -> Total2 | AI5: 3 | AU5: =_xlfn.CONCAT(AU7,AI5) -> Parcial3 | AV5: =_xlfn.CONCAT(AV7,AI5) -> Total3 | AX5: 4 | BJ5: =_xlfn.CONCAT(BJ7,AX5) -> Parcial4 | BK5: =_xlfn.CONCAT(BK7,AX5) -> Total4 | BM5: 5 | BY5: =_xlfn.CONCAT(BY7,BM5) -> Parcial5 | BZ5: =_xlfn.CONCAT(BZ7,BM5) -> Total5
D6: Ano 1 | T6: Ano 2 | AI6: Ano 3 | AX6: Ano 4 | BM6: Ano 5
B7: =1 -> 1 | C7: Meta 1 | D7: R$ | E7: Jan | F7: Fev | G7: Mar | H7: Abr | I7: Mai | J7: Jun | K7: Jul | L7: Ago | M7: Set | N7: Out | O7: Nov | P7: Dez | Q7: Parcial | R7: Total | T7: Jan | U7: Fev | V7: Mar | W7: Abr | X7: Mai | Y7: Jun | Z7: Jul | AA7: Ago | AB7: Set | AC7: Out | AD7: Nov | AE7: Dez | AF7: Parcial | AG7: Total | AI7: Jan | AJ7: Fev | AK7: Mar | AL7: Abr | AM7: Mai | AN7: Jun | AO7: Jul | AP7: Ago | AQ7: Set | AR7: Out | AS7: Nov | AT7: Dez | AU7: Parcial | AV7: Total | AX7: Jan | AY7: Fev | AZ7: Mar | BA7: Abr | BB7: Mai | BC7: Jun | BD7: Jul | BE7: Ago | BF7: Set | BG7: Out | BH7: Nov | BI7: Dez | BJ7: Parcial | BK7: Total | BM7: Jan | BN7: Fev | BO7: Mar | BP7: Abr | BQ7: Mai | BR7: Jun | BS7: Jul | BT7: Ago | BU7: Set | BV7: Out | BW7: Nov | BX7: Dez | BY7: Parcial | BZ7: Total
A8: =_xlfn.CONCAT(D8,B7) -> Planejado1 | C8: =C59 -> Aumentar: Faturamento | D8: Planejado | Q8: =SUMIF(E86:P86,"=1",E8:P8) -> 0 | R8: =SUM(E8:P8) -> 0 | AF8: =SUMIF(T86:AE86,"=1",T8:AE8) -> 0 | AG8: =SUM(T8:AE8) -> 0 | AU8: =SUMIF(AI86:AT86,"=1",AI8:AT8) -> 0 | AV8: =SUM(AI8:AT8) -> 0 | BJ8: =SUMIF(AX86:BI86,"=1",AX8:BI8) -> 0 | BK8: =SUM(AX8:BI8) -> 0 | BY8: =SUMIF(BM86:BX86,"=1",BM8:BX8) -> 0 | BZ8: =SUM(BM8:BX8) -> 0
A9: =_xlfn.CONCAT(D9,B7) -> Realizado1 | D9: Realizado | Q9: =SUMIF(E86:P86,"=1",E9:P9) -> 0 | R9: =SUM(E9:P9) -> 0 | AF9: =SUMIF(T86:AE86,"=1",T9:AE9) -> 0 | AG9: =SUM(T9:AE9) -> 0 | AU9: =SUMIF(AI86:AT86,"=1",AI9:AT9) -> 0 | AV9: =SUM(AI9:AT9) -> 0 | BJ9: =SUMIF(AX86:BI86,"=1",AX9:BI9) -> 0 | BK9: =SUM(AX9:BI9) -> 0 | BY9: =SUMIF(BM86:BX86,"=1",BM9:BX9) -> 0 | BZ9: =SUM(BM9:BX9) -> 0
D10: Percentual | E10: =IF(OR(ISERR(E9/E8-1),E9=""),"",IF($A59=parametros!$I$3,E8/E9-1,E9/E8-1)) | F10: =IF(OR(ISERR(F9/F8-1),F9=""),"",IF($A59=parametros!$I$3,F8/F9-1,F9/F8-1)) | G10: =IF(OR(ISERR(G9/G8-1),G9=""),"",IF($A59=parametros!$I$3,G8/G9-1,G9/G8-1)) | H10: =IF(OR(ISERR(H9/H8-1),H9=""),"",IF($A59=parametros!$I$3,H8/H9-1,H9/H8-1)) | I10: =IF(OR(ISERR(I9/I8-1),I9=""),"",IF($A59=parametros!$I$3,I8/I9-1,I9/I8-1)) | J10: =IF(OR(ISERR(J9/J8-1),J9=""),"",IF($A59=parametros!$I$3,J8/J9-1,J9/J8-1)) | K10: =IF(OR(ISERR(K9/K8-1),K9=""),"",IF($A59=parametros!$I$3,K8/K9-1,K9/K8-1)) | L10: =IF(OR(ISERR(L9/L8-1),L9=""),"",IF($A59=parametros!$I$3,L8/L9-1,L9/L8-1)) | ... R10: =IF(OR(ISERR(R9/R8-1),R9=""),"",IF($A59=parametros!$I$3,R8/R9-1,R9/R8-1)) | T10: =IF(OR(ISERR(T9/T8-1),T9=""),"",IF($A59=parametros!$I$3,T8/T9-1,T9/T8-1)) | U10: =IF(OR(ISERR(U9/U8-1),U9=""),"",IF($A59=parametros!$I$3,U8/U9-1,U9/U8-1)) | V10: =IF(OR(ISERR(V9/V8-1),V9=""),"",IF($A59=parametros!$I$3,V8/V9-1,V9/V8-1)) | W10: =IF(OR(ISERR(W9/W8-1),W9=""),"",IF($A59=parametros!$I$3,W8/W9-1,W9/W8-1)) | X10: =IF(OR(ISERR(X9/X8-1),X9=""),"",IF($A59=parametros!$I$3,X8/X9-1,X9/X8-1)) | Y10: =IF(OR(ISERR(Y9/Y8-1),Y9=""),"",IF($A59=parametros!$I$3,Y8/Y9-1,Y9/Y8-1)) | Z10: =IF(OR(ISERR(Z9/Z8-1),Z9=""),"",IF($A59=parametros!$I$3,Z8/Z9-1,Z9/Z8-1)) | AA10: =IF(OR(ISERR(AA9/AA8-1),AA9=""),"",IF($A59=parametros!$I$3,AA8/AA9-1,AA9/AA8-1)) | ... AG10: =IF(OR(ISERR(AG9/AG8-1),AG9=""),"",IF($A59=parametros!$I$3,AG8/AG9-1,AG9/AG8-1)) | AI10: =IF(OR(ISERR(AI9/AI8-1),AI9=""),"",IF($A59=parametros!$I$3,AI8/AI9-1,AI9/AI8-1)) | AJ10: =IF(OR(ISERR(AJ9/AJ8-1),AJ9=""),"",IF($A59=parametros!$I$3,AJ8/AJ9-1,AJ9/AJ8-1)) | AK10: =IF(OR(ISERR(AK9/AK8-1),AK9=""),"",IF($A59=parametros!$I$3,AK8/AK9-1,AK9/AK8-1)) | AL10: =IF(OR(ISERR(AL9/AL8-1),AL9=""),"",IF($A59=parametros!$I$3,AL8/AL9-1,AL9/AL8-1)) | AM10: =IF(OR(ISERR(AM9/AM8-1),AM9=""),"",IF($A59=parametros!$I$3,AM8/AM9-1,AM9/AM8-1)) | AN10: =IF(OR(ISERR(AN9/AN8-1),AN9=""),"",IF($A59=parametros!$I$3,AN8/AN9-1,AN9/AN8-1)) | AO10: =IF(OR(ISERR(AO9/AO8-1),AO9=""),"",IF($A59=parametros!$I$3,AO8/AO9-1,AO9/AO8-1)) | AP10: =IF(OR(ISERR(AP9/AP8-1),AP9=""),"",IF($A59=parametros!$I$3,AP8/AP9-1,AP9/AP8-1)) | ... AV10: =IF(OR(ISERR(AV9/AV8-1),AV9=""),"",IF($A59=parametros!$I$3,AV8/AV9-1,AV9/AV8-1)) | AX10: =IF(OR(ISERR(AX9/AX8-1),AX9=""),"",IF($A59=parametros!$I$3,AX8/AX9-1,AX9/AX8-1)) | AY10: =IF(OR(ISERR(AY9/AY8-1),AY9=""),"",IF($A59=parametros!$I$3,AY8/AY9-1,AY9/AY8-1)) | AZ10: =IF(OR(ISERR(AZ9/AZ8-1),AZ9=""),"",IF($A59=parametros!$I$3,AZ8/AZ9-1,AZ9/AZ8-1)) | BA10: =IF(OR(ISERR(BA9/BA8-1),BA9=""),"",IF($A59=parametros!$I$3,BA8/BA9-1,BA9/BA8-1)) | BB10: =IF(OR(ISERR(BB9/BB8-1),BB9=""),"",IF($A59=parametros!$I$3,BB8/BB9-1,BB9/BB8-1)) | BC10: =IF(OR(ISERR(BC9/BC8-1),BC9=""),"",IF($A59=parametros!$I$3,BC8/BC9-1,BC9/BC8-1)) | BD10: =IF(OR(ISERR(BD9/BD8-1),BD9=""),"",IF($A59=parametros!$I$3,BD8/BD9-1,BD9/BD8-1)) | BE10: =IF(OR(ISERR(BE9/BE8-1),BE9=""),"",IF($A59=parametros!$I$3,BE8/BE9-1,BE9/BE8-1)) | ... BK10: =IF(OR(ISERR(BK9/BK8-1),BK9=""),"",IF($A59=parametros!$I$3,BK8/BK9-1,BK9/BK8-1)) | BM10: =IF(OR(ISERR(BM9/BM8-1),BM9=""),"",IF($A59=parametros!$I$3,BM8/BM9-1,BM9/BM8-1)) | BN10: =IF(OR(ISERR(BN9/BN8-1),BN9=""),"",IF($A59=parametros!$I$3,BN8/BN9-1,BN9/BN8-1)) | BO10: =IF(OR(ISERR(BO9/BO8-1),BO9=""),"",IF($A59=parametros!$I$3,BO8/BO9-1,BO9/BO8-1)) | BP10: =IF(OR(ISERR(BP9/BP8-1),BP9=""),"",IF($A59=parametros!$I$3,BP8/BP9-1,BP9/BP8-1)) | BQ10: =IF(OR(ISERR(BQ9/BQ8-1),BQ9=""),"",IF($A59=parametros!$I$3,BQ8/BQ9-1,BQ9/BQ8-1)) | BR10: =IF(OR(ISERR(BR9/BR8-1),BR9=""),"",IF($A59=parametros!$I$3,BR8/BR9-1,BR9/BR8-1)) | BS10: =IF(OR(ISERR(BS9/BS8-1),BS9=""),"",IF($A59=parametros!$I$3,BS8/BS9-1,BS9/BS8-1)) | BT10: =IF(OR(ISERR(BT9/BT8-1),BT9=""),"",IF($A59=parametros!$I$3,BT8/BT9-1,BT9/BT8-1)) | ... BZ10: =IF(OR(ISERR(BZ9/BZ8-1),BZ9=""),"",IF($A59=parametros!$I$3,BZ8/BZ9-1,BZ9/BZ8-1))
B12: =2 -> 2 | C12: Meta 2 | D12: Número | E12: Jan | F12: Fev | G12: Mar | H12: Abr | I12: Mai | J12: Jun | K12: Jul | L12: Ago | M12: Set | N12: Out | O12: Nov | P12: Dez | Q12: Parcial | R12: Total | T12: Jan | U12: Fev | V12: Mar | W12: Abr | X12: Mai | Y12: Jun | Z12: Jul | AA12: Ago | AB12: Set | AC12: Out | AD12: Nov | AE12: Dez | AF12: Parcial | AG12: Total | AI12: Jan | AJ12: Fev | AK12: Mar | AL12: Abr | AM12: Mai | AN12: Jun | AO12: Jul | AP12: Ago | AQ12: Set | AR12: Out | AS12: Nov | AT12: Dez | AU12: Parcial | AV12: Total | AX12: Jan | AY12: Fev | AZ12: Mar | BA12: Abr | BB12: Mai | BC12: Jun | BD12: Jul | BE12: Ago | BF12: Set | BG12: Out | BH12: Nov | BI12: Dez | BJ12: Parcial | BK12: Total | BM12: Jan | BN12: Fev | BO12: Mar | BP12: Abr | BQ12: Mai | BR12: Jun | BS12: Jul | BT12: Ago | BU12: Set | BV12: Out | BW12: Nov | BX12: Dez | BY12: Parcial | BZ12: Total
A13: =_xlfn.CONCAT(D13,B12) -> Planejado2 | C13: =C60 -> Aumentar: Tiket Médio | D13: Planejado | Q13: =SUMIF(E88:P88,"=1",E13:P13) -> 0 | R13: =SUM(E13:P13) -> 0 | AF13: =SUMIF(T88:AE88,"=1",T13:AE13) -> 0 | AG13: =SUM(T13:AE13) -> 0 | AU13: =SUMIF(AI88:AT88,"=1",AI13:AT13) -> 0 | AV13: =SUM(AI13:AT13) -> 0 | BJ13: =SUMIF(AX88:BI88,"=1",AX13:BI13) -> 0 | BK13: =SUM(AX13:BI13) -> 0 | BY13: =SUMIF(BM88:BX88,"=1",BM13:BX13) -> 0 | BZ13: =SUM(BM13:BX13) -> 0
A14: =_xlfn.CONCAT(D14,B12) -> Realizado2 | D14: Realizado | Q14: =SUMIF(E88:P88,"=1",E14:P14) -> 0 | R14: =SUM(E14:P14) -> 0 | AF14: =SUMIF(T88:AE88,"=1",T14:AE14) -> 0 | AG14: =SUM(T14:AE14) -> 0 | AU14: =SUMIF(AI88:AT88,"=1",AI14:AT14) -> 0 | AV14: =SUM(AI14:AT14) -> 0 | BJ14: =SUMIF(AX88:BI88,"=1",AX14:BI14) -> 0 | BK14: =SUM(AX14:BI14) -> 0 | BY14: =SUMIF(BM88:BX88,"=1",BM14:BX14) -> 0 | BZ14: =SUM(BM14:BX14) -> 0
D15: Percentual | E15: =IF(OR(ISERR(E14/E13-1),E14=""),"",IF($A64=parametros!$I$3,E13/E14-1,E14/E13-1)) | F15: =IF(OR(ISERR(F14/F13-1),F14=""),"",IF($A64=parametros!$I$3,F13/F14-1,F14/F13-1)) | G15: =IF(OR(ISERR(G14/G13-1),G14=""),"",IF($A64=parametros!$I$3,G13/G14-1,G14/G13-1)) | H15: =IF(OR(ISERR(H14/H13-1),H14=""),"",IF($A64=parametros!$I$3,H13/H14-1,H14/H13-1)) | I15: =IF(OR(ISERR(I14/I13-1),I14=""),"",IF($A64=parametros!$I$3,I13/I14-1,I14/I13-1)) | J15: =IF(OR(ISERR(J14/J13-1),J14=""),"",IF($A64=parametros!$I$3,J13/J14-1,J14/J13-1)) | K15: =IF(OR(ISERR(K14/K13-1),K14=""),"",IF($A64=parametros!$I$3,K13/K14-1,K14/K13-1)) | L15: =IF(OR(ISERR(L14/L13-1),L14=""),"",IF($A64=parametros!$I$3,L13/L14-1,L14/L13-1)) | ... R15: =IF(OR(ISERR(R14/R13-1),R14=""),"",IF($A64=parametros!$I$3,R13/R14-1,R14/R13-1)) | T15: =IF(OR(ISERR(T14/T13-1),T14=""),"",IF($A64=parametros!$I$3,T13/T14-1,T14/T13-1)) | U15: =IF(OR(ISERR(U14/U13-1),U14=""),"",IF($A64=parametros!$I$3,U13/U14-1,U14/U13-1)) | V15: =IF(OR(ISERR(V14/V13-1),V14=""),"",IF($A64=parametros!$I$3,V13/V14-1,V14/V13-1)) | W15: =IF(OR(ISERR(W14/W13-1),W14=""),"",IF($A64=parametros!$I$3,W13/W14-1,W14/W13-1)) | X15: =IF(OR(ISERR(X14/X13-1),X14=""),"",IF($A64=parametros!$I$3,X13/X14-1,X14/X13-1)) | Y15: =IF(OR(ISERR(Y14/Y13-1),Y14=""),"",IF($A64=parametros!$I$3,Y13/Y14-1,Y14/Y13-1)) | Z15: =IF(OR(ISERR(Z14/Z13-1),Z14=""),"",IF($A64=parametros!$I$3,Z13/Z14-1,Z14/Z13-1)) | AA15: =IF(OR(ISERR(AA14/AA13-1),AA14=""),"",IF($A64=parametros!$I$3,AA13/AA14-1,AA14/AA13-1)) | ... AG15: =IF(OR(ISERR(AG14/AG13-1),AG14=""),"",IF($A64=parametros!$I$3,AG13/AG14-1,AG14/AG13-1)) | AI15: =IF(OR(ISERR(AI14/AI13-1),AI14=""),"",IF($A64=parametros!$I$3,AI13/AI14-1,AI14/AI13-1)) | AJ15: =IF(OR(ISERR(AJ14/AJ13-1),AJ14=""),"",IF($A64=parametros!$I$3,AJ13/AJ14-1,AJ14/AJ13-1)) | AK15: =IF(OR(ISERR(AK14/AK13-1),AK14=""),"",IF($A64=parametros!$I$3,AK13/AK14-1,AK14/AK13-1)) | AL15: =IF(OR(ISERR(AL14/AL13-1),AL14=""),"",IF($A64=parametros!$I$3,AL13/AL14-1,AL14/AL13-1)) | AM15: =IF(OR(ISERR(AM14/AM13-1),AM14=""),"",IF($A64=parametros!$I$3,AM13/AM14-1,AM14/AM13-1)) | AN15: =IF(OR(ISERR(AN14/AN13-1),AN14=""),"",IF($A64=parametros!$I$3,AN13/AN14-1,AN14/AN13-1)) | AO15: =IF(OR(ISERR(AO14/AO13-1),AO14=""),"",IF($A64=parametros!$I$3,AO13/AO14-1,AO14/AO13-1)) | AP15: =IF(OR(ISERR(AP14/AP13-1),AP14=""),"",IF($A64=parametros!$I$3,AP13/AP14-1,AP14/AP13-1)) | ... AV15: =IF(OR(ISERR(AV14/AV13-1),AV14=""),"",IF($A64=parametros!$I$3,AV13/AV14-1,AV14/AV13-1)) | AX15: =IF(OR(ISERR(AX14/AX13-1),AX14=""),"",IF($A64=parametros!$I$3,AX13/AX14-1,AX14/AX13-1)) | AY15: =IF(OR(ISERR(AY14/AY13-1),AY14=""),"",IF($A64=parametros!$I$3,AY13/AY14-1,AY14/AY13-1)) | AZ15: =IF(OR(ISERR(AZ14/AZ13-1),AZ14=""),"",IF($A64=parametros!$I$3,AZ13/AZ14-1,AZ14/AZ13-1)) | BA15: =IF(OR(ISERR(BA14/BA13-1),BA14=""),"",IF($A64=parametros!$I$3,BA13/BA14-1,BA14/BA13-1)) | BB15: =IF(OR(ISERR(BB14/BB13-1),BB14=""),"",IF($A64=parametros!$I$3,BB13/BB14-1,BB14/BB13-1)) | BC15: =IF(OR(ISERR(BC14/BC13-1),BC14=""),"",IF($A64=parametros!$I$3,BC13/BC14-1,BC14/BC13-1)) | BD15: =IF(OR(ISERR(BD14/BD13-1),BD14=""),"",IF($A64=parametros!$I$3,BD13/BD14-1,BD14/BD13-1)) | BE15: =IF(OR(ISERR(BE14/BE13-1),BE14=""),"",IF($A64=parametros!$I$3,BE13/BE14-1,BE14/BE13-1)) | ... BK15: =IF(OR(ISERR(BK14/BK13-1),BK14=""),"",IF($A64=parametros!$I$3,BK13/BK14-1,BK14/BK13-1)) | BM15: =IF(OR(ISERR(BM14/BM13-1),BM14=""),"",IF($A64=parametros!$I$3,BM13/BM14-1,BM14/BM13-1)) | BN15: =IF(OR(ISERR(BN14/BN13-1),BN14=""),"",IF($A64=parametros!$I$3,BN13/BN14-1,BN14/BN13-1)) | BO15: =IF(OR(ISERR(BO14/BO13-1),BO14=""),"",IF($A64=parametros!$I$3,BO13/BO14-1,BO14/BO13-1)) | BP15: =IF(OR(ISERR(BP14/BP13-1),BP14=""),"",IF($A64=parametros!$I$3,BP13/BP14-1,BP14/BP13-1)) | BQ15: =IF(OR(ISERR(BQ14/BQ13-1),BQ14=""),"",IF($A64=parametros!$I$3,BQ13/BQ14-1,BQ14/BQ13-1)) | BR15: =IF(OR(ISERR(BR14/BR13-1),BR14=""),"",IF($A64=parametros!$I$3,BR13/BR14-1,BR14/BR13-1)) | BS15: =IF(OR(ISERR(BS14/BS13-1),BS14=""),"",IF($A64=parametros!$I$3,BS13/BS14-1,BS14/BS13-1)) | BT15: =IF(OR(ISERR(BT14/BT13-1),BT14=""),"",IF($A64=parametros!$I$3,BT13/BT14-1,BT14/BT13-1)) | ... BZ15: =IF(OR(ISERR(BZ14/BZ13-1),BZ14=""),"",IF($A64=parametros!$I$3,BZ13/BZ14-1,BZ14/BZ13-1))
B17: =3 -> 3 | C17: Meta 3 | D17: Número | E17: Jan | F17: Fev | G17: Mar | H17: Abr | I17: Mai | J17: Jun | K17: Jul | L17: Ago | M17: Set | N17: Out | O17: Nov | P17: Dez | Q17: Parcial | R17: Total | T17: Jan | U17: Fev | V17: Mar | W17: Abr | X17: Mai | Y17: Jun | Z17: Jul | AA17: Ago | AB17: Set | AC17: Out | AD17: Nov | AE17: Dez | AF17: Parcial | AG17: Total | AI17: Jan | AJ17: Fev | AK17: Mar | AL17: Abr | AM17: Mai | AN17: Jun | AO17: Jul | AP17: Ago | AQ17: Set | AR17: Out | AS17: Nov | AT17: Dez | AU17: Parcial | AV17: Total | AX17: Jan | AY17: Fev | AZ17: Mar | BA17: Abr | BB17: Mai | BC17: Jun | BD17: Jul | BE17: Ago | BF17: Set | BG17: Out | BH17: Nov | BI17: Dez | BJ17: Parcial | BK17: Total | BM17: Jan | BN17: Fev | BO17: Mar | BP17: Abr | BQ17: Mai | BR17: Jun | BS17: Jul | BT17: Ago | BU17: Set | BV17: Out | BW17: Nov | BX17: Dez | BY17: Parcial | BZ17: Total
A18: =_xlfn.CONCAT(D18,B17) -> Planejado3 | C18: =C61 -> : | D18: Planejado | Q18: =SUMIF(E90:P90,"=1",E18:P18) -> 0 | R18: =SUM(E18:P18) -> 0 | AF18: =SUMIF(T90:AE90,"=1",T18:AE18) -> 0 | AG18: =SUM(T18:AE18) -> 0 | AU18: =SUMIF(AI90:AT90,"=1",AI18:AT18) -> 0 | AV18: =SUM(AI18:AT18) -> 0 | BJ18: =SUMIF(AX90:BI90,"=1",AX18:BI18) -> 0 | BK18: =SUM(AX18:BI18) -> 0 | BY18: =SUMIF(BM90:BX90,"=1",BM18:BX18) -> 0 | BZ18: =SUM(BM18:BX18) -> 0
A19: =_xlfn.CONCAT(D19,B17) -> Realizado3 | D19: Realizado | Q19: =SUMIF(E90:P90,"=1",E19:P19) -> 0 | R19: =SUM(E19:P19) -> 0 | AF19: =SUMIF(T90:AE90,"=1",T19:AE19) -> 0 | AG19: =SUM(T19:AE19) -> 0 | AU19: =SUMIF(AI90:AT90,"=1",AI19:AT19) -> 0 | AV19: =SUM(AI19:AT19) -> 0 | BJ19: =SUMIF(AX90:BI90,"=1",AX19:BI19) -> 0 | BK19: =SUM(AX19:BI19) -> 0 | BY19: =SUMIF(BM90:BX90,"=1",BM19:BX19) -> 0 | BZ19: =SUM(BM19:BX19) -> 0
D20: Percentual | E20: =IF(OR(ISERR(E19/E18-1),E19=""),"",IF($B69=parametros!$I$3,E18/E19-1,E19/E18-1)) | F20: =IF(OR(ISERR(F19/F18-1),F19=""),"",IF($B69=parametros!$I$3,F18/F19-1,F19/F18-1)) | G20: =IF(OR(ISERR(G19/G18-1),G19=""),"",IF($B69=parametros!$I$3,G18/G19-1,G19/G18-1)) | H20: =IF(OR(ISERR(H19/H18-1),H19=""),"",IF($B69=parametros!$I$3,H18/H19-1,H19/H18-1)) | I20: =IF(OR(ISERR(I19/I18-1),I19=""),"",IF($B69=parametros!$I$3,I18/I19-1,I19/I18-1)) | J20: =IF(OR(ISERR(J19/J18-1),J19=""),"",IF($B69=parametros!$I$3,J18/J19-1,J19/J18-1)) | K20: =IF(OR(ISERR(K19/K18-1),K19=""),"",IF($B69=parametros!$I$3,K18/K19-1,K19/K18-1)) | L20: =IF(OR(ISERR(L19/L18-1),L19=""),"",IF($B69=parametros!$I$3,L18/L19-1,L19/L18-1)) | ... R20: =IF(OR(ISERR(R19/R18-1),R19=""),"",IF($B69=parametros!$I$3,R18/R19-1,R19/R18-1)) | T20: =IF(OR(ISERR(T19/T18-1),T19=""),"",IF($B69=parametros!$I$3,T18/T19-1,T19/T18-1)) | U20: =IF(OR(ISERR(U19/U18-1),U19=""),"",IF($B69=parametros!$I$3,U18/U19-1,U19/U18-1)) | V20: =IF(OR(ISERR(V19/V18-1),V19=""),"",IF($B69=parametros!$I$3,V18/V19-1,V19/V18-1)) | W20: =IF(OR(ISERR(W19/W18-1),W19=""),"",IF($B69=parametros!$I$3,W18/W19-1,W19/W18-1)) | X20: =IF(OR(ISERR(X19/X18-1),X19=""),"",IF($B69=parametros!$I$3,X18/X19-1,X19/X18-1)) | Y20: =IF(OR(ISERR(Y19/Y18-1),Y19=""),"",IF($B69=parametros!$I$3,Y18/Y19-1,Y19/Y18-1)) | Z20: =IF(OR(ISERR(Z19/Z18-1),Z19=""),"",IF($B69=parametros!$I$3,Z18/Z19-1,Z19/Z18-1)) | AA20: =IF(OR(ISERR(AA19/AA18-1),AA19=""),"",IF($B69=parametros!$I$3,AA18/AA19-1,AA19/AA18-1)) | ... AG20: =IF(OR(ISERR(AG19/AG18-1),AG19=""),"",IF($B69=parametros!$I$3,AG18/AG19-1,AG19/AG18-1)) | AI20: =IF(OR(ISERR(AI19/AI18-1),AI19=""),"",IF($B69=parametros!$I$3,AI18/AI19-1,AI19/AI18-1)) | AJ20: =IF(OR(ISERR(AJ19/AJ18-1),AJ19=""),"",IF($B69=parametros!$I$3,AJ18/AJ19-1,AJ19/AJ18-1)) | AK20: =IF(OR(ISERR(AK19/AK18-1),AK19=""),"",IF($B69=parametros!$I$3,AK18/AK19-1,AK19/AK18-1)) | AL20: =IF(OR(ISERR(AL19/AL18-1),AL19=""),"",IF($B69=parametros!$I$3,AL18/AL19-1,AL19/AL18-1)) | AM20: =IF(OR(ISERR(AM19/AM18-1),AM19=""),"",IF($B69=parametros!$I$3,AM18/AM19-1,AM19/AM18-1)) | AN20: =IF(OR(ISERR(AN19/AN18-1),AN19=""),"",IF($B69=parametros!$I$3,AN18/AN19-1,AN19/AN18-1)) | AO20: =IF(OR(ISERR(AO19/AO18-1),AO19=""),"",IF($B69=parametros!$I$3,AO18/AO19-1,AO19/AO18-1)) | AP20: =IF(OR(ISERR(AP19/AP18-1),AP19=""),"",IF($B69=parametros!$I$3,AP18/AP19-1,AP19/AP18-1)) | ... AV20: =IF(OR(ISERR(AV19/AV18-1),AV19=""),"",IF($B69=parametros!$I$3,AV18/AV19-1,AV19/AV18-1)) | AX20: =IF(OR(ISERR(AX19/AX18-1),AX19=""),"",IF($B69=parametros!$I$3,AX18/AX19-1,AX19/AX18-1)) | AY20: =IF(OR(ISERR(AY19/AY18-1),AY19=""),"",IF($B69=parametros!$I$3,AY18/AY19-1,AY19/AY18-1)) | AZ20: =IF(OR(ISERR(AZ19/AZ18-1),AZ19=""),"",IF($B69=parametros!$I$3,AZ18/AZ19-1,AZ19/AZ18-1)) | BA20: =IF(OR(ISERR(BA19/BA18-1),BA19=""),"",IF($B69=parametros!$I$3,BA18/BA19-1,BA19/BA18-1)) | BB20: =IF(OR(ISERR(BB19/BB18-1),BB19=""),"",IF($B69=parametros!$I$3,BB18/BB19-1,BB19/BB18-1)) | BC20: =IF(OR(ISERR(BC19/BC18-1),BC19=""),"",IF($B69=parametros!$I$3,BC18/BC19-1,BC19/BC18-1)) | BD20: =IF(OR(ISERR(BD19/BD18-1),BD19=""),"",IF($B69=parametros!$I$3,BD18/BD19-1,BD19/BD18-1)) | BE20: =IF(OR(ISERR(BE19/BE18-1),BE19=""),"",IF($B69=parametros!$I$3,BE18/BE19-1,BE19/BE18-1)) | ... BK20: =IF(OR(ISERR(BK19/BK18-1),BK19=""),"",IF($B69=parametros!$I$3,BK18/BK19-1,BK19/BK18-1)) | BM20: =IF(OR(ISERR(BM19/BM18-1),BM19=""),"",IF($B69=parametros!$I$3,BM18/BM19-1,BM19/BM18-1)) | BN20: =IF(OR(ISERR(BN19/BN18-1),BN19=""),"",IF($B69=parametros!$I$3,BN18/BN19-1,BN19/BN18-1)) | BO20: =IF(OR(ISERR(BO19/BO18-1),BO19=""),"",IF($B69=parametros!$I$3,BO18/BO19-1,BO19/BO18-1)) | BP20: =IF(OR(ISERR(BP19/BP18-1),BP19=""),"",IF($B69=parametros!$I$3,BP18/BP19-1,BP19/BP18-1)) | BQ20: =IF(OR(ISERR(BQ19/BQ18-1),BQ19=""),"",IF($B69=parametros!$I$3,BQ18/BQ19-1,BQ19/BQ18-1)) | BR20: =IF(OR(ISERR(BR19/BR18-1),BR19=""),"",IF($B69=parametros!$I$3,BR18/BR19-1,BR19/BR18-1)) | BS20: =IF(OR(ISERR(BS19/BS18-1),BS19=""),"",IF($B69=parametros!$I$3,BS18/BS19-1,BS19/BS18-1)) | BT20: =IF(OR(ISERR(BT19/BT18-1),BT19=""),"",IF($B69=parametros!$I$3,BT18/BT19-1,BT19/BT18-1)) | ... BZ20: =IF(OR(ISERR(BZ19/BZ18-1),BZ19=""),"",IF($B69=parametros!$I$3,BZ18/BZ19-1,BZ19/BZ18-1))
B22: =4 -> 4 | C22: Meta 4 | D22: Número | E22: Jan | F22: Fev | G22: Mar | H22: Abr | I22: Mai | J22: Jun | K22: Jul | L22: Ago | M22: Set | N22: Out | O22: Nov | P22: Dez | Q22: Parcial | R22: Total | T22: Jan | U22: Fev | V22: Mar | W22: Abr | X22: Mai | Y22: Jun | Z22: Jul | AA22: Ago | AB22: Set | AC22: Out | AD22: Nov | AE22: Dez | AF22: Parcial | AG22: Total | AI22: Jan | AJ22: Fev | AK22: Mar | AL22: Abr | AM22: Mai | AN22: Jun | AO22: Jul | AP22: Ago | AQ22: Set | AR22: Out | AS22: Nov | AT22: Dez | AU22: Parcial | AV22: Total | AX22: Jan | AY22: Fev | AZ22: Mar | BA22: Abr | BB22: Mai | BC22: Jun | BD22: Jul | BE22: Ago | BF22: Set | BG22: Out | BH22: Nov | BI22: Dez | BJ22: Parcial | BK22: Total | BM22: Jan | BN22: Fev | BO22: Mar | BP22: Abr | BQ22: Mai | BR22: Jun | BS22: Jul | BT22: Ago | BU22: Set | BV22: Out | BW22: Nov | BX22: Dez | BY22: Parcial | BZ22: Total
A23: =_xlfn.CONCAT(D23,B22) -> Planejado4 | C23: =C62 -> : | D23: Planejado | Q23: =SUMIF(E92:P92,"=1",E23:P23) -> 0 | R23: =SUM(E23:P23) -> 0 | AF23: =SUMIF(T92:AE92,"=1",T23:AE23) -> 0 | AG23: =SUM(T23:AE23) -> 0 | AU23: =SUMIF(AI92:AT92,"=1",AI23:AT23) -> 0 | AV23: =SUM(AI23:AT23) -> 0 | BJ23: =SUMIF(AX92:BI92,"=1",AX23:BI23) -> 0 | BK23: =SUM(AX23:BI23) -> 0 | BY23: =SUMIF(BM92:BX92,"=1",BM23:BX23) -> 0 | BZ23: =SUM(BM23:BX23) -> 0
A24: =_xlfn.CONCAT(D24,B22) -> Realizado4 | D24: Realizado | Q24: =SUMIF(E92:P92,"=1",E24:P24) -> 0 | R24: =SUM(E24:P24) -> 0 | AF24: =SUMIF(T92:AE92,"=1",T24:AE24) -> 0 | AG24: =SUM(T24:AE24) -> 0 | AU24: =SUMIF(AI92:AT92,"=1",AI24:AT24) -> 0 | AV24: =SUM(AI24:AT24) -> 0 | BJ24: =SUMIF(AX92:BI92,"=1",AX24:BI24) -> 0 | BK24: =SUM(AX24:BI24) -> 0 | BY24: =SUMIF(BM92:BX92,"=1",BM24:BX24) -> 0 | BZ24: =SUM(BM24:BX24) -> 0
D25: Percentual | E25: =IF(OR(ISERR(E24/E23-1),E24=""),"",IF($B74=parametros!$I$3,E23/E24-1,E24/E23-1)) | F25: =IF(OR(ISERR(F24/F23-1),F24=""),"",IF($B74=parametros!$I$3,F23/F24-1,F24/F23-1)) | G25: =IF(OR(ISERR(G24/G23-1),G24=""),"",IF($B74=parametros!$I$3,G23/G24-1,G24/G23-1)) | H25: =IF(OR(ISERR(H24/H23-1),H24=""),"",IF($B74=parametros!$I$3,H23/H24-1,H24/H23-1)) | I25: =IF(OR(ISERR(I24/I23-1),I24=""),"",IF($B74=parametros!$I$3,I23/I24-1,I24/I23-1)) | J25: =IF(OR(ISERR(J24/J23-1),J24=""),"",IF($B74=parametros!$I$3,J23/J24-1,J24/J23-1)) | K25: =IF(OR(ISERR(K24/K23-1),K24=""),"",IF($B74=parametros!$I$3,K23/K24-1,K24/K23-1)) | L25: =IF(OR(ISERR(L24/L23-1),L24=""),"",IF($B74=parametros!$I$3,L23/L24-1,L24/L23-1)) | ... R25: =IF(OR(ISERR(R24/R23-1),R24=""),"",IF($B74=parametros!$I$3,R23/R24-1,R24/R23-1)) | T25: =IF(OR(ISERR(T24/T23-1),T24=""),"",IF($B74=parametros!$I$3,T23/T24-1,T24/T23-1)) | U25: =IF(OR(ISERR(U24/U23-1),U24=""),"",IF($B74=parametros!$I$3,U23/U24-1,U24/U23-1)) | V25: =IF(OR(ISERR(V24/V23-1),V24=""),"",IF($B74=parametros!$I$3,V23/V24-1,V24/V23-1)) | W25: =IF(OR(ISERR(W24/W23-1),W24=""),"",IF($B74=parametros!$I$3,W23/W24-1,W24/W23-1)) | X25: =IF(OR(ISERR(X24/X23-1),X24=""),"",IF($B74=parametros!$I$3,X23/X24-1,X24/X23-1)) | Y25: =IF(OR(ISERR(Y24/Y23-1),Y24=""),"",IF($B74=parametros!$I$3,Y23/Y24-1,Y24/Y23-1)) | Z25: =IF(OR(ISERR(Z24/Z23-1),Z24=""),"",IF($B74=parametros!$I$3,Z23/Z24-1,Z24/Z23-1)) | AA25: =IF(OR(ISERR(AA24/AA23-1),AA24=""),"",IF($B74=parametros!$I$3,AA23/AA24-1,AA24/AA23-1)) | ... AG25: =IF(OR(ISERR(AG24/AG23-1),AG24=""),"",IF($B74=parametros!$I$3,AG23/AG24-1,AG24/AG23-1)) | AI25: =IF(OR(ISERR(AI24/AI23-1),AI24=""),"",IF($B74=parametros!$I$3,AI23/AI24-1,AI24/AI23-1)) | AJ25: =IF(OR(ISERR(AJ24/AJ23-1),AJ24=""),"",IF($B74=parametros!$I$3,AJ23/AJ24-1,AJ24/AJ23-1)) | AK25: =IF(OR(ISERR(AK24/AK23-1),AK24=""),"",IF($B74=parametros!$I$3,AK23/AK24-1,AK24/AK23-1)) | AL25: =IF(OR(ISERR(AL24/AL23-1),AL24=""),"",IF($B74=parametros!$I$3,AL23/AL24-1,AL24/AL23-1)) | AM25: =IF(OR(ISERR(AM24/AM23-1),AM24=""),"",IF($B74=parametros!$I$3,AM23/AM24-1,AM24/AM23-1)) | AN25: =IF(OR(ISERR(AN24/AN23-1),AN24=""),"",IF($B74=parametros!$I$3,AN23/AN24-1,AN24/AN23-1)) | AO25: =IF(OR(ISERR(AO24/AO23-1),AO24=""),"",IF($B74=parametros!$I$3,AO23/AO24-1,AO24/AO23-1)) | AP25: =IF(OR(ISERR(AP24/AP23-1),AP24=""),"",IF($B74=parametros!$I$3,AP23/AP24-1,AP24/AP23-1)) | ... AV25: =IF(OR(ISERR(AV24/AV23-1),AV24=""),"",IF($B74=parametros!$I$3,AV23/AV24-1,AV24/AV23-1)) | AX25: =IF(OR(ISERR(AX24/AX23-1),AX24=""),"",IF($B74=parametros!$I$3,AX23/AX24-1,AX24/AX23-1)) | AY25: =IF(OR(ISERR(AY24/AY23-1),AY24=""),"",IF($B74=parametros!$I$3,AY23/AY24-1,AY24/AY23-1)) | AZ25: =IF(OR(ISERR(AZ24/AZ23-1),AZ24=""),"",IF($B74=parametros!$I$3,AZ23/AZ24-1,AZ24/AZ23-1)) | BA25: =IF(OR(ISERR(BA24/BA23-1),BA24=""),"",IF($B74=parametros!$I$3,BA23/BA24-1,BA24/BA23-1)) | BB25: =IF(OR(ISERR(BB24/BB23-1),BB24=""),"",IF($B74=parametros!$I$3,BB23/BB24-1,BB24/BB23-1)) | BC25: =IF(OR(ISERR(BC24/BC23-1),BC24=""),"",IF($B74=parametros!$I$3,BC23/BC24-1,BC24/BC23-1)) | BD25: =IF(OR(ISERR(BD24/BD23-1),BD24=""),"",IF($B74=parametros!$I$3,BD23/BD24-1,BD24/BD23-1)) | BE25: =IF(OR(ISERR(BE24/BE23-1),BE24=""),"",IF($B74=parametros!$I$3,BE23/BE24-1,BE24/BE23-1)) | ... BK25: =IF(OR(ISERR(BK24/BK23-1),BK24=""),"",IF($B74=parametros!$I$3,BK23/BK24-1,BK24/BK23-1)) | BM25: =IF(OR(ISERR(BM24/BM23-1),BM24=""),"",IF($B74=parametros!$I$3,BM23/BM24-1,BM24/BM23-1)) | BN25: =IF(OR(ISERR(BN24/BN23-1),BN24=""),"",IF($B74=parametros!$I$3,BN23/BN24-1,BN24/BN23-1)) | BO25: =IF(OR(ISERR(BO24/BO23-1),BO24=""),"",IF($B74=parametros!$I$3,BO23/BO24-1,BO24/BO23-1)) | BP25: =IF(OR(ISERR(BP24/BP23-1),BP24=""),"",IF($B74=parametros!$I$3,BP23/BP24-1,BP24/BP23-1)) | BQ25: =IF(OR(ISERR(BQ24/BQ23-1),BQ24=""),"",IF($B74=parametros!$I$3,BQ23/BQ24-1,BQ24/BQ23-1)) | BR25: =IF(OR(ISERR(BR24/BR23-1),BR24=""),"",IF($B74=parametros!$I$3,BR23/BR24-1,BR24/BR23-1)) | BS25: =IF(OR(ISERR(BS24/BS23-1),BS24=""),"",IF($B74=parametros!$I$3,BS23/BS24-1,BS24/BS23-1)) | BT25: =IF(OR(ISERR(BT24/BT23-1),BT24=""),"",IF($B74=parametros!$I$3,BT23/BT24-1,BT24/BT23-1)) | ... BZ25: =IF(OR(ISERR(BZ24/BZ23-1),BZ24=""),"",IF($B74=parametros!$I$3,BZ23/BZ24-1,BZ24/BZ23-1))
B27: =5 -> 5 | C27: Meta 5 | D27: Número | E27: Jan | F27: Fev | G27: Mar | H27: Abr | I27: Mai | J27: Jun | K27: Jul | L27: Ago | M27: Set | N27: Out | O27: Nov | P27: Dez | Q27: Parcial | R27: Total | T27: Jan | U27: Fev | V27: Mar | W27: Abr | X27: Mai | Y27: Jun | Z27: Jul | AA27: Ago | AB27: Set | AC27: Out | AD27: Nov | AE27: Dez | AF27: Parcial | AG27: Total | AI27: Jan | AJ27: Fev | AK27: Mar | AL27: Abr | AM27: Mai | AN27: Jun | AO27: Jul | AP27: Ago | AQ27: Set | AR27: Out | AS27: Nov | AT27: Dez | AU27: Parcial | AV27: Total | AX27: Jan | AY27: Fev | AZ27: Mar | BA27: Abr | BB27: Mai | BC27: Jun | BD27: Jul | BE27: Ago | BF27: Set | BG27: Out | BH27: Nov | BI27: Dez | BJ27: Parcial | BK27: Total | BM27: Jan | BN27: Fev | BO27: Mar | BP27: Abr | BQ27: Mai | BR27: Jun | BS27: Jul | BT27: Ago | BU27: Set | BV27: Out | BW27: Nov | BX27: Dez | BY27: Parcial | BZ27: Total
A28: =_xlfn.CONCAT(D28,B27) -> Planejado5 | C28: =C63 -> : | D28: Planejado | Q28: =SUMIF(E94:P94,"=1",E28:P28) -> 0 | R28: =SUM(E28:P28) -> 0 | AF28: =SUMIF(T94:AE94,"=1",T28:AE28) -> 0 | AG28: =SUM(T28:AE28) -> 0 | AU28: =SUMIF(AI94:AT94,"=1",AI28:AT28) -> 0 | AV28: =SUM(AI28:AT28) -> 0 | BJ28: =SUMIF(AX94:BI94,"=1",AX28:BI28) -> 0 | BK28: =SUM(AX28:BI28) -> 0 | BY28: =SUMIF(BM94:BX94,"=1",BM28:BX28) -> 0 | BZ28: =SUM(BM28:BX28) -> 0
A29: =_xlfn.CONCAT(D29,B27) -> Realizado5 | D29: Realizado | Q29: =SUMIF(E94:P94,"=1",E29:P29) -> 0 | R29: =SUM(E29:P29) -> 0 | AF29: =SUMIF(T94:AE94,"=1",T29:AE29) -> 0 | AG29: =SUM(T29:AE29) -> 0 | AU29: =SUMIF(AI94:AT94,"=1",AI29:AT29) -> 0 | AV29: =SUM(AI29:AT29) -> 0 | BJ29: =SUMIF(AX94:BI94,"=1",AX29:BI29) -> 0 | BK29: =SUM(AX29:BI29) -> 0 | BY29: =SUMIF(BM94:BX94,"=1",BM29:BX29) -> 0 | BZ29: =SUM(BM29:BX29) -> 0
D30: Percentual | E30: =IF(OR(ISERR(E29/E28-1),E29=""),"",IF($B79=parametros!$I$3,E28/E29-1,E29/E28-1)) | F30: =IF(OR(ISERR(F29/F28-1),F29=""),"",IF($B79=parametros!$I$3,F28/F29-1,F29/F28-1)) | G30: =IF(OR(ISERR(G29/G28-1),G29=""),"",IF($B79=parametros!$I$3,G28/G29-1,G29/G28-1)) | H30: =IF(OR(ISERR(H29/H28-1),H29=""),"",IF($B79=parametros!$I$3,H28/H29-1,H29/H28-1)) | I30: =IF(OR(ISERR(I29/I28-1),I29=""),"",IF($B79=parametros!$I$3,I28/I29-1,I29/I28-1)) | J30: =IF(OR(ISERR(J29/J28-1),J29=""),"",IF($B79=parametros!$I$3,J28/J29-1,J29/J28-1)) | K30: =IF(OR(ISERR(K29/K28-1),K29=""),"",IF($B79=parametros!$I$3,K28/K29-1,K29/K28-1)) | L30: =IF(OR(ISERR(L29/L28-1),L29=""),"",IF($B79=parametros!$I$3,L28/L29-1,L29/L28-1)) | ... R30: =IF(OR(ISERR(R29/R28-1),R29=""),"",IF($B79=parametros!$I$3,R28/R29-1,R29/R28-1)) | T30: =IF(OR(ISERR(T29/T28-1),T29=""),"",IF($B79=parametros!$I$3,T28/T29-1,T29/T28-1)) | U30: =IF(OR(ISERR(U29/U28-1),U29=""),"",IF($B79=parametros!$I$3,U28/U29-1,U29/U28-1)) | V30: =IF(OR(ISERR(V29/V28-1),V29=""),"",IF($B79=parametros!$I$3,V28/V29-1,V29/V28-1)) | W30: =IF(OR(ISERR(W29/W28-1),W29=""),"",IF($B79=parametros!$I$3,W28/W29-1,W29/W28-1)) | X30: =IF(OR(ISERR(X29/X28-1),X29=""),"",IF($B79=parametros!$I$3,X28/X29-1,X29/X28-1)) | Y30: =IF(OR(ISERR(Y29/Y28-1),Y29=""),"",IF($B79=parametros!$I$3,Y28/Y29-1,Y29/Y28-1)) | Z30: =IF(OR(ISERR(Z29/Z28-1),Z29=""),"",IF($B79=parametros!$I$3,Z28/Z29-1,Z29/Z28-1)) | AA30: =IF(OR(ISERR(AA29/AA28-1),AA29=""),"",IF($B79=parametros!$I$3,AA28/AA29-1,AA29/AA28-1)) | ... AG30: =IF(OR(ISERR(AG29/AG28-1),AG29=""),"",IF($B79=parametros!$I$3,AG28/AG29-1,AG29/AG28-1)) | AI30: =IF(OR(ISERR(AI29/AI28-1),AI29=""),"",IF($B79=parametros!$I$3,AI28/AI29-1,AI29/AI28-1)) | AJ30: =IF(OR(ISERR(AJ29/AJ28-1),AJ29=""),"",IF($B79=parametros!$I$3,AJ28/AJ29-1,AJ29/AJ28-1)) | AK30: =IF(OR(ISERR(AK29/AK28-1),AK29=""),"",IF($B79=parametros!$I$3,AK28/AK29-1,AK29/AK28-1)) | AL30: =IF(OR(ISERR(AL29/AL28-1),AL29=""),"",IF($B79=parametros!$I$3,AL28/AL29-1,AL29/AL28-1)) | AM30: =IF(OR(ISERR(AM29/AM28-1),AM29=""),"",IF($B79=parametros!$I$3,AM28/AM29-1,AM29/AM28-1)) | AN30: =IF(OR(ISERR(AN29/AN28-1),AN29=""),"",IF($B79=parametros!$I$3,AN28/AN29-1,AN29/AN28-1)) | AO30: =IF(OR(ISERR(AO29/AO28-1),AO29=""),"",IF($B79=parametros!$I$3,AO28/AO29-1,AO29/AO28-1)) | AP30: =IF(OR(ISERR(AP29/AP28-1),AP29=""),"",IF($B79=parametros!$I$3,AP28/AP29-1,AP29/AP28-1)) | ... AV30: =IF(OR(ISERR(AV29/AV28-1),AV29=""),"",IF($B79=parametros!$I$3,AV28/AV29-1,AV29/AV28-1)) | AX30: =IF(OR(ISERR(AX29/AX28-1),AX29=""),"",IF($B79=parametros!$I$3,AX28/AX29-1,AX29/AX28-1)) | AY30: =IF(OR(ISERR(AY29/AY28-1),AY29=""),"",IF($B79=parametros!$I$3,AY28/AY29-1,AY29/AY28-1)) | AZ30: =IF(OR(ISERR(AZ29/AZ28-1),AZ29=""),"",IF($B79=parametros!$I$3,AZ28/AZ29-1,AZ29/AZ28-1)) | BA30: =IF(OR(ISERR(BA29/BA28-1),BA29=""),"",IF($B79=parametros!$I$3,BA28/BA29-1,BA29/BA28-1)) | BB30: =IF(OR(ISERR(BB29/BB28-1),BB29=""),"",IF($B79=parametros!$I$3,BB28/BB29-1,BB29/BB28-1)) | BC30: =IF(OR(ISERR(BC29/BC28-1),BC29=""),"",IF($B79=parametros!$I$3,BC28/BC29-1,BC29/BC28-1)) | BD30: =IF(OR(ISERR(BD29/BD28-1),BD29=""),"",IF($B79=parametros!$I$3,BD28/BD29-1,BD29/BD28-1)) | BE30: =IF(OR(ISERR(BE29/BE28-1),BE29=""),"",IF($B79=parametros!$I$3,BE28/BE29-1,BE29/BE28-1)) | ... BK30: =IF(OR(ISERR(BK29/BK28-1),BK29=""),"",IF($B79=parametros!$I$3,BK28/BK29-1,BK29/BK28-1)) | BM30: =IF(OR(ISERR(BM29/BM28-1),BM29=""),"",IF($B79=parametros!$I$3,BM28/BM29-1,BM29/BM28-1)) | BN30: =IF(OR(ISERR(BN29/BN28-1),BN29=""),"",IF($B79=parametros!$I$3,BN28/BN29-1,BN29/BN28-1)) | BO30: =IF(OR(ISERR(BO29/BO28-1),BO29=""),"",IF($B79=parametros!$I$3,BO28/BO29-1,BO29/BO28-1)) | BP30: =IF(OR(ISERR(BP29/BP28-1),BP29=""),"",IF($B79=parametros!$I$3,BP28/BP29-1,BP29/BP28-1)) | BQ30: =IF(OR(ISERR(BQ29/BQ28-1),BQ29=""),"",IF($B79=parametros!$I$3,BQ28/BQ29-1,BQ29/BQ28-1)) | BR30: =IF(OR(ISERR(BR29/BR28-1),BR29=""),"",IF($B79=parametros!$I$3,BR28/BR29-1,BR29/BR28-1)) | BS30: =IF(OR(ISERR(BS29/BS28-1),BS29=""),"",IF($B79=parametros!$I$3,BS28/BS29-1,BS29/BS28-1)) | BT30: =IF(OR(ISERR(BT29/BT28-1),BT29=""),"",IF($B79=parametros!$I$3,BT28/BT29-1,BT29/BT28-1)) | ... BZ30: =IF(OR(ISERR(BZ29/BZ28-1),BZ29=""),"",IF($B79=parametros!$I$3,BZ28/BZ29-1,BZ29/BZ28-1))
B32: =6 -> 6 | C32: Meta 6 | D32: Número | E32: Jan | F32: Fev | G32: Mar | H32: Abr | I32: Mai | J32: Jun | K32: Jul | L32: Ago | M32: Set | N32: Out | O32: Nov | P32: Dez | Q32: Parcial | R32: Total | T32: Jan | U32: Fev | V32: Mar | W32: Abr | X32: Mai | Y32: Jun | Z32: Jul | AA32: Ago | AB32: Set | AC32: Out | AD32: Nov | AE32: Dez | AF32: Parcial | AG32: Total | AI32: Jan | AJ32: Fev | AK32: Mar | AL32: Abr | AM32: Mai | AN32: Jun | AO32: Jul | AP32: Ago | AQ32: Set | AR32: Out | AS32: Nov | AT32: Dez | AU32: Parcial | AV32: Total | AX32: Jan | AY32: Fev | AZ32: Mar | BA32: Abr | BB32: Mai | BC32: Jun | BD32: Jul | BE32: Ago | BF32: Set | BG32: Out | BH32: Nov | BI32: Dez | BJ32: Parcial | BK32: Total | BM32: Jan | BN32: Fev | BO32: Mar | BP32: Abr | BQ32: Mai | BR32: Jun | BS32: Jul | BT32: Ago | BU32: Set | BV32: Out | BW32: Nov | BX32: Dez | BY32: Parcial | BZ32: Total
A33: =_xlfn.CONCAT(D33,B32) -> Planejado6 | C33: =C64 -> : | D33: Planejado | Q33: =SUMIF(E96:P96,"=1",E33:P33) -> 0 | R33: =SUM(E33:P33) -> 0 | AF33: =SUMIF(T96:AE96,"=1",T33:AE33) -> 0 | AG33: =SUM(T33:AE33) -> 0 | AU33: =SUMIF(AI96:AT96,"=1",AI33:AT33) -> 0 | AV33: =SUM(AI33:AT33) -> 0 | BJ33: =SUMIF(AX96:BI96,"=1",AX33:BI33) -> 0 | BK33: =SUM(AX33:BI33) -> 0 | BY33: =SUMIF(BM96:BX96,"=1",BM33:BX33) -> 0 | BZ33: =SUM(BM33:BX33) -> 0
A34: =_xlfn.CONCAT(D34,B32) -> Realizado6 | D34: Realizado | Q34: =SUMIF(E96:P96,"=1",E34:P34) -> 0 | R34: =SUM(E34:P34) -> 0 | AF34: =SUMIF(T96:AE96,"=1",T34:AE34) -> 0 | AG34: =SUM(T34:AE34) -> 0 | AU34: =SUMIF(AI96:AT96,"=1",AI34:AT34) -> 0 | AV34: =SUM(AI34:AT34) -> 0 | BJ34: =SUMIF(AX96:BI96,"=1",AX34:BI34) -> 0 | BK34: =SUM(AX34:BI34) -> 0 | BY34: =SUMIF(BM96:BX96,"=1",BM34:BX34) -> 0 | BZ34: =SUM(BM34:BX34) -> 0
D35: Percentual | E35: =IF(OR(ISERR(E34/E33-1),E34=""),"",IF($B85=parametros!$I$3,E33/E34-1,E34/E33-1)) | F35: =IF(OR(ISERR(F34/F33-1),F34=""),"",IF($B85=parametros!$I$3,F33/F34-1,F34/F33-1)) | G35: =IF(OR(ISERR(G34/G33-1),G34=""),"",IF($B85=parametros!$I$3,G33/G34-1,G34/G33-1)) | H35: =IF(OR(ISERR(H34/H33-1),H34=""),"",IF($B85=parametros!$I$3,H33/H34-1,H34/H33-1)) | I35: =IF(OR(ISERR(I34/I33-1),I34=""),"",IF($B85=parametros!$I$3,I33/I34-1,I34/I33-1)) | J35: =IF(OR(ISERR(J34/J33-1),J34=""),"",IF($B85=parametros!$I$3,J33/J34-1,J34/J33-1)) | K35: =IF(OR(ISERR(K34/K33-1),K34=""),"",IF($B85=parametros!$I$3,K33/K34-1,K34/K33-1)) | L35: =IF(OR(ISERR(L34/L33-1),L34=""),"",IF($B85=parametros!$I$3,L33/L34-1,L34/L33-1)) | ... R35: =IF(OR(ISERR(R34/R33-1),R34=""),"",IF($B85=parametros!$I$3,R33/R34-1,R34/R33-1)) | T35: =IF(OR(ISERR(T34/T33-1),T34=""),"",IF($B85=parametros!$I$3,T33/T34-1,T34/T33-1)) | U35: =IF(OR(ISERR(U34/U33-1),U34=""),"",IF($B85=parametros!$I$3,U33/U34-1,U34/U33-1)) | V35: =IF(OR(ISERR(V34/V33-1),V34=""),"",IF($B85=parametros!$I$3,V33/V34-1,V34/V33-1)) | W35: =IF(OR(ISERR(W34/W33-1),W34=""),"",IF($B85=parametros!$I$3,W33/W34-1,W34/W33-1)) | X35: =IF(OR(ISERR(X34/X33-1),X34=""),"",IF($B85=parametros!$I$3,X33/X34-1,X34/X33-1)) | Y35: =IF(OR(ISERR(Y34/Y33-1),Y34=""),"",IF($B85=parametros!$I$3,Y33/Y34-1,Y34/Y33-1)) | Z35: =IF(OR(ISERR(Z34/Z33-1),Z34=""),"",IF($B85=parametros!$I$3,Z33/Z34-1,Z34/Z33-1)) | AA35: =IF(OR(ISERR(AA34/AA33-1),AA34=""),"",IF($B85=parametros!$I$3,AA33/AA34-1,AA34/AA33-1)) | ... AG35: =IF(OR(ISERR(AG34/AG33-1),AG34=""),"",IF($B85=parametros!$I$3,AG33/AG34-1,AG34/AG33-1)) | AI35: =IF(OR(ISERR(AI34/AI33-1),AI34=""),"",IF($B85=parametros!$I$3,AI33/AI34-1,AI34/AI33-1)) | AJ35: =IF(OR(ISERR(AJ34/AJ33-1),AJ34=""),"",IF($B85=parametros!$I$3,AJ33/AJ34-1,AJ34/AJ33-1)) | AK35: =IF(OR(ISERR(AK34/AK33-1),AK34=""),"",IF($B85=parametros!$I$3,AK33/AK34-1,AK34/AK33-1)) | AL35: =IF(OR(ISERR(AL34/AL33-1),AL34=""),"",IF($B85=parametros!$I$3,AL33/AL34-1,AL34/AL33-1)) | AM35: =IF(OR(ISERR(AM34/AM33-1),AM34=""),"",IF($B85=parametros!$I$3,AM33/AM34-1,AM34/AM33-1)) | AN35: =IF(OR(ISERR(AN34/AN33-1),AN34=""),"",IF($B85=parametros!$I$3,AN33/AN34-1,AN34/AN33-1)) | AO35: =IF(OR(ISERR(AO34/AO33-1),AO34=""),"",IF($B85=parametros!$I$3,AO33/AO34-1,AO34/AO33-1)) | AP35: =IF(OR(ISERR(AP34/AP33-1),AP34=""),"",IF($B85=parametros!$I$3,AP33/AP34-1,AP34/AP33-1)) | ... AV35: =IF(OR(ISERR(AV34/AV33-1),AV34=""),"",IF($B85=parametros!$I$3,AV33/AV34-1,AV34/AV33-1)) | AX35: =IF(OR(ISERR(AX34/AX33-1),AX34=""),"",IF($B85=parametros!$I$3,AX33/AX34-1,AX34/AX33-1)) | AY35: =IF(OR(ISERR(AY34/AY33-1),AY34=""),"",IF($B85=parametros!$I$3,AY33/AY34-1,AY34/AY33-1)) | AZ35: =IF(OR(ISERR(AZ34/AZ33-1),AZ34=""),"",IF($B85=parametros!$I$3,AZ33/AZ34-1,AZ34/AZ33-1)) | BA35: =IF(OR(ISERR(BA34/BA33-1),BA34=""),"",IF($B85=parametros!$I$3,BA33/BA34-1,BA34/BA33-1)) | BB35: =IF(OR(ISERR(BB34/BB33-1),BB34=""),"",IF($B85=parametros!$I$3,BB33/BB34-1,BB34/BB33-1)) | BC35: =IF(OR(ISERR(BC34/BC33-1),BC34=""),"",IF($B85=parametros!$I$3,BC33/BC34-1,BC34/BC33-1)) | BD35: =IF(OR(ISERR(BD34/BD33-1),BD34=""),"",IF($B85=parametros!$I$3,BD33/BD34-1,BD34/BD33-1)) | BE35: =IF(OR(ISERR(BE34/BE33-1),BE34=""),"",IF($B85=parametros!$I$3,BE33/BE34-1,BE34/BE33-1)) | ... BK35: =IF(OR(ISERR(BK34/BK33-1),BK34=""),"",IF($B85=parametros!$I$3,BK33/BK34-1,BK34/BK33-1)) | BM35: =IF(OR(ISERR(BM34/BM33-1),BM34=""),"",IF($B85=parametros!$I$3,BM33/BM34-1,BM34/BM33-1)) | BN35: =IF(OR(ISERR(BN34/BN33-1),BN34=""),"",IF($B85=parametros!$I$3,BN33/BN34-1,BN34/BN33-1)) | BO35: =IF(OR(ISERR(BO34/BO33-1),BO34=""),"",IF($B85=parametros!$I$3,BO33/BO34-1,BO34/BO33-1)) | BP35: =IF(OR(ISERR(BP34/BP33-1),BP34=""),"",IF($B85=parametros!$I$3,BP33/BP34-1,BP34/BP33-1)) | BQ35: =IF(OR(ISERR(BQ34/BQ33-1),BQ34=""),"",IF($B85=parametros!$I$3,BQ33/BQ34-1,BQ34/BQ33-1)) | BR35: =IF(OR(ISERR(BR34/BR33-1),BR34=""),"",IF($B85=parametros!$I$3,BR33/BR34-1,BR34/BR33-1)) | BS35: =IF(OR(ISERR(BS34/BS33-1),BS34=""),"",IF($B85=parametros!$I$3,BS33/BS34-1,BS34/BS33-1)) | BT35: =IF(OR(ISERR(BT34/BT33-1),BT34=""),"",IF($B85=parametros!$I$3,BT33/BT34-1,BT34/BT33-1)) | ... BZ35: =IF(OR(ISERR(BZ34/BZ33-1),BZ34=""),"",IF($B85=parametros!$I$3,BZ33/BZ34-1,BZ34/BZ33-1))
B37: =7 -> 7 | C37: Meta 7 | D37: Número | E37: Jan | F37: Fev | G37: Mar | H37: Abr | I37: Mai | J37: Jun | K37: Jul | L37: Ago | M37: Set | N37: Out | O37: Nov | P37: Dez | Q37: Parcial | R37: Total | T37: Jan | U37: Fev | V37: Mar | W37: Abr | X37: Mai | Y37: Jun | Z37: Jul | AA37: Ago | AB37: Set | AC37: Out | AD37: Nov | AE37: Dez | AF37: Parcial | AG37: Total | AI37: Jan | AJ37: Fev | AK37: Mar | AL37: Abr | AM37: Mai | AN37: Jun | AO37: Jul | AP37: Ago | AQ37: Set | AR37: Out | AS37: Nov | AT37: Dez | AU37: Parcial | AV37: Total | AX37: Jan | AY37: Fev | AZ37: Mar | BA37: Abr | BB37: Mai | BC37: Jun | BD37: Jul | BE37: Ago | BF37: Set | BG37: Out | BH37: Nov | BI37: Dez | BJ37: Parcial | BK37: Total | BM37: Jan | BN37: Fev | BO37: Mar | BP37: Abr | BQ37: Mai | BR37: Jun | BS37: Jul | BT37: Ago | BU37: Set | BV37: Out | BW37: Nov | BX37: Dez | BY37: Parcial | BZ37: Total
A38: =_xlfn.CONCAT(D38,B37) -> Planejado7 | C38: =C65 -> : | D38: Planejado | Q38: =SUMIF(E98:P98,"=1",E38:P38) -> 0 | R38: =SUM(E38:P38) -> 0 | AF38: =SUMIF(T98:AE98,"=1",T38:AE38) -> 0 | AG38: =SUM(T38:AE38) -> 0 | AU38: =SUMIF(AI98:AT98,"=1",AI38:AT38) -> 0 | AV38: =SUM(AI38:AT38) -> 0 | BJ38: =SUMIF(AX98:BI98,"=1",AX38:BI38) -> 0 | BK38: =SUM(AX38:BI38) -> 0 | BY38: =SUMIF(BM98:BX98,"=1",BM38:BX38) -> 0 | BZ38: =SUM(BM38:BX38) -> 0
A39: =_xlfn.CONCAT(D39,B37) -> Realizado7 | D39: Realizado | Q39: =SUMIF(E98:P98,"=1",E39:P39) -> 0 | R39: =SUM(E39:P39) -> 0 | AF39: =SUMIF(T98:AE98,"=1",T39:AE39) -> 0 | AG39: =SUM(T39:AE39) -> 0 | AU39: =SUMIF(AI98:AT98,"=1",AI39:AT39) -> 0 | AV39: =SUM(AI39:AT39) -> 0 | BJ39: =SUMIF(AX98:BI98,"=1",AX39:BI39) -> 0 | BK39: =SUM(AX39:BI39) -> 0 | BY39: =SUMIF(BM98:BX98,"=1",BM39:BX39) -> 0 | BZ39: =SUM(BM39:BX39) -> 0
